Workbook

Sheet Calendar
A1: 📅 MONTHLY TASK CALENDAR
A4: Select Month: | C4: 1 | D4: Year: | E4: 2026 | G4: =TEXT(DATE(E4,C4,1),"MMMM YYYY") -> January 2026
A6: Sunday | C6: Monday | E6: Tuesday | G6: Wednesday | I6: Thursday | K6: Friday | M6: Saturday
A7: ✓ | B7: Task | C7: ✓ | D7: Task | E7: ✓ | F7: Task | G7: ✓ | H7: Task | I7: ✓ | J7: Task | K7: ✓ | L7: Task | M7: ✓ | N7: Task
A8: =IF(AND(1-WEEKDAY(DATE($E$4,$C$4,1))+1>=1,1-WEEKDAY(DATE($E$4,$C$4,1))+1<=DAY(EOMONTH(DATE($E$4,$C$4,1),0))),1-WEEKDAY(DATE($E$4,$C$4,1))+1,"") | C8: =IF(AND(2-WEEKDAY(DATE($E$4,$C$4,1))+1>=1,2-WEEKDAY(DATE($E$4,$C$4,1))+1<=DAY(EOMONTH(DATE($E$4,$C$4,1),0))),2-WEEKDAY(DATE($E$4,$C$4,1))+1,"") | E8: =IF(AND(3-WEEKDAY(DATE($E$4,$C$4,1))+1>=1,3-WEEKDAY(DATE($E$4,$C$4,1))+1<=DAY(EOMONTH(DATE($E$4,$C$4,1),0))),3-WEEKDAY(DATE($E$4,$C$4,1))+1,"") | G8: =IF(AND(4-WEEKDAY(DATE($E$4,$C$4,1))+1>=1,4-WEEKDAY(DATE($E$4,$C$4,1))+1<=DAY(EOMONTH(DATE($E$4,$C$4,1),0))),4-WEEKDAY(DATE($E$4,$C$4,1))+1,"") | I8: =IF(AND(5-WEEKDAY(DATE($E$4,$C$4,1))+1>=1,5-WEEKDAY(DATE($E$4,$C$4,1))+1<=DAY(EOMONTH(DATE($E$4,$C$4,1),0))),5-WEEKDAY(DATE($E$4,$C$4,1))+1,"") -> 1 | K8: =IF(AND(6-WEEKDAY(DATE($E$4,$C$4,1))+1>=1,6-WEEKDAY(DATE($E$4,$C$4,1))+1<=DAY(EOMONTH(DATE($E$4,$C$4,1),0))),6-WEEKDAY(DATE($E$4,$C$4,1))+1,"") -> 2 | M8: =IF(AND(7-WEEKDAY(DATE($E$4,$C$4,1))+1>=1,7-WEEKDAY(DATE($E$4,$C$4,1))+1<=DAY(EOMONTH(DATE($E$4,$C$4,1),0))),7-WEEKDAY(DATE($E$4,$C$4,1))+1,"") -> 3
G9: ✓ | H9: Team standup meeting | J9: Sprint planning
H10: Review PRs
A14: =IF(AND(8-WEEKDAY(DATE($E$4,$C$4,1))+1>=1,8-WEEKDAY(DATE($E$4,$C$4,1))+1<=DAY(EOMONTH(DATE($E$4,$C$4,1),0))),8-WEEKDAY(DATE($E$4,$C$4,1))+1,"") -> 4 | C14: =IF(AND(9-WEEKDAY(DATE($E$4,$C$4,1))+1>=1,9-WEEKDAY(DATE($E$4,$C$4,1))+1<=DAY(EOMONTH(DATE($E$4,$C$4,1),0))),9-WEEKDAY(DATE($E$4,$C$4,1))+1,"") -> 5 | E14: =IF(AND(10-WEEKDAY(DATE($E$4,$C$4,1))+1>=1,10-WEEKDAY(DATE($E$4,$C$4,1))+1<=DAY(EOMONTH(DATE($E$4,$C$4,1),0))),10-WEEKDAY(DATE($E$4,$C$4,1))+1,"") -> 6 | G14: =IF(AND(11-WEEKDAY(DATE($E$4,$C$4,1))+1>=1,11-WEEKDAY(DATE($E$4,$C$4,1))+1<=DAY(EOMONTH(DATE($E$4,$C$4,1),0))),11-WEEKDAY(DATE($E$4,$C$4,1))+1,"") -> 7 | I14: =IF(AND(12-WEEKDAY(DATE($E$4,$C$4,1))+1>=1,12-WEEKDAY(DATE($E$4,$C$4,1))+1<=DAY(EOMONTH(DATE($E$4,$C$4,1),0))),12-WEEKDAY(DATE($E$4,$C$4,1))+1,"") -> 8 | K14: =IF(AND(13-WEEKDAY(DATE($E$4,$C$4,1))+1>=1,13-WEEKDAY(DATE($E$4,$C$4,1))+1<=DAY(EOMONTH(DATE($E$4,$C$4,1),0))),13-WEEKDAY(DATE($E$4,$C$4,1))+1,"") -> 9 | M14: =IF(AND(14-WEEKDAY(DATE($E$4,$C$4,1))+1>=1,14-WEEKDAY(DATE($E$4,$C$4,1))+1<=DAY(EOMONTH(DATE($E$4,$C$4,1),0))),14-WEEKDAY(DATE($E$4,$C$4,1))+1,"") -> 10
D15: Process mining workshop | E15: ✓ | F15: AI model review | H15: Client presentation | J15: Documentation update
D16: Data extraction
A20: =IF(AND(15-WEEKDAY(DATE($E$4,$C$4,1))+1>=1,15-WEEKDAY(DATE($E$4,$C$4,1))+1<=DAY(EOMONTH(DATE($E$4,$C$4,1),0))),15-WEEKDAY(DATE($E$4,$C$4,1))+1,"") -> 11 | C20: =IF(AND(16-WEEKDAY(DATE($E$4,$C$4,1))+1>=1,16-WEEKDAY(DATE($E$4,$C$4,1))+1<=DAY(EOMONTH(DATE($E$4,$C$4,1),0))),16-WEEKDAY(DATE($E$4,$C$4,1))+1,"") -> 12 | E20: =IF(AND(17-WEEKDAY(DATE($E$4,$C$4,1))+1>=1,17-WEEKDAY(DATE($E$4,$C$4,1))+1<=DAY(EOMONTH(DATE($E$4,$C$4,1),0))),17-WEEKDAY(DATE($E$4,$C$4,1))+1,"") -> 13 | G20: =IF(AND(18-WEEKDAY(DATE($E$4,$C$4,1))+1>=1,18-WEEKDAY(DATE($E$4,$C$4,1))+1<=DAY(EOMONTH(DATE($E$4,$C$4,1),0))),18-WEEKDAY(DATE($E$4,$C$4,1))+1,"") -> 14 | I20: =IF(AND(19-WEEKDAY(DATE($E$4,$C$4,1))+1>=1,19-WEEKDAY(DATE($E$4,$C$4,1))+1<=DAY(EOMONTH(DATE($E$4,$C$4,1),0))),19-WEEKDAY(DATE($E$4,$C$4,1))+1,"") -> 15 | K20: =IF(AND(20-WEEKDAY(DATE($E$4,$C$4,1))+1>=1,20-WEEKDAY(DATE($E$4,$C$4,1))+1<=DAY(EOMONTH(DATE($E$4,$C$4,1),0))),20-WEEKDAY(DATE($E$4,$C$4,1))+1,"") -> 16 | M20: =IF(AND(21-WEEKDAY(DATE($E$4,$C$4,1))+1>=1,21-WEEKDAY(DATE($E$4,$C$4,1))+1<=DAY(EOMONTH(DATE($E$4,$C$4,1),0))),21-WEEKDAY(DATE($E$4,$C$4,1))+1,"") -> 17
B21: Weekly report | D21: Code refactoring | F21: Testing session | H21: Deployment prep
A26: =IF(AND(22-WEEKDAY(DATE($E$4,$C$4,1))+1>=1,22-WEEKDAY(DATE($E$4,$C$4,1))+1<=DAY(EOMONTH(DATE($E$4,$C$4,1),0))),22-WEEKDAY(DATE($E$4,$C$4,1))+1,"") -> 18 | C26: =IF(AND(23-WEEKDAY(DATE($E$4,$C$4,1))+1>=1,23-WEEKDAY(DATE($E$4,$C$4,1))+1<=DAY(EOMONTH(DATE($E$4,$C$4,1),0))),23-WEEKDAY(DATE($E$4,$C$4,1))+1,"") -> 19 | E26: =IF(AND(24-WEEKDAY(DATE($E$4,$C$4,1))+1>=1,24-WEEKDAY(DATE($E$4,$C$4,1))+1<=DAY(EOMONTH(DATE($E$4,$C$4,1),0))),24-WEEKDAY(DATE($E$4,$C$4,1))+1,"") -> 20 | G26: =IF(AND(25-WEEKDAY(DATE($E$4,$C$4,1))+1>=1,25-WEEKDAY(DATE($E$4,$C$4,1))+1<=DAY(EOMONTH(DATE($E$4,$C$4,1),0))),25-WEEKDAY(DATE($E$4,$C$4,1))+1,"") -> 21 | I26: =IF(AND(26-WEEKDAY(DATE($E$4,$C$4,1))+1>=1,26-WEEKDAY(DATE($E$4,$C$4,1))+1<=DAY(EOMONTH(DATE($E$4,$C$4,1),0))),26-WEEKDAY(DATE($E$4,$C$4,1))+1,"") -> 22 | K26: =IF(AND(27-WEEKDAY(DATE($E$4,$C$4,1))+1>=1,27-WEEKDAY(DATE($E$4,$C$4,1))+1<=DAY(EOMONTH(DATE($E$4,$C$4,1),0))),27-WEEKDAY(DATE($E$4,$C$4,1))+1,"") -> 23 | M26: =IF(AND(28-WEEKDAY(DATE($E$4,$C$4,1))+1>=1,28-WEEKDAY(DATE($E$4,$C$4,1))+1<=DAY(EOMONTH(DATE($E$4,$C$4,1),0))),28-WEEKDAY(DATE($E$4,$C$4,1))+1,"") -> 24
A32: =IF(AND(29-WEEKDAY(DATE($E$4,$C$4,1))+1>=1,29-WEEKDAY(DATE($E$4,$C$4,1))+1<=DAY(EOMONTH(DATE($E$4,$C$4,1),0))),29-WEEKDAY(DATE($E$4,$C$4,1))+1,"") -> 25 | C32: =IF(AND(30-WEEKDAY(DATE($E$4,$C$4,1))+1>=1,30-WEEKDAY(DATE($E$4,$C$4,1))+1<=DAY(EOMONTH(DATE($E$4,$C$4,1),0))),30-WEEKDAY(DATE($E$4,$C$4,1))+1,"") -> 26 | E32: =IF(AND(31-WEEKDAY(DATE($E$4,$C$4,1))+1>=1,31-WEEKDAY(DATE($E$4,$C$4,1))+1<=DAY(EOMONTH(DATE($E$4,$C$4,1),0))),31-WEEKDAY(DATE($E$4,$C$4,1))+1,"") -> 27 | G32: =IF(AND(32-WEEKDAY(DATE($E$4,$C$4,1))+1>=1,32-WEEKDAY(DATE($E$4,$C$4,1))+1<=DAY(EOMONTH(DATE($E$4,$C$4,1),0))),32-WEEKDAY(DATE($E$4,$C$4,1))+1,"") -> 28 | I32: =IF(AND(33-WEEKDAY(DATE($E$4,$C$4,1))+1>=1,33-WEEKDAY(DATE($E$4,$C$4,1))+1<=DAY(EOMONTH(DATE($E$4,$C$4,1),0))),33-WEEKDAY(DATE($E$4,$C$4,1))+1,"") -> 29 | K32: =IF(AND(34-WEEKDAY(DATE($E$4,$C$4,1))+1>=1,34-WEEKDAY(DATE($E$4,$C$4,1))+1<=DAY(EOMONTH(DATE($E$4,$C$4,1),0))),34-WEEKDAY(DATE($E$4,$C$4,1))+1,"") -> 30 | M32: =IF(AND(35-WEEKDAY(DATE($E$4,$C$4,1))+1>=1,35-WEEKDAY(DATE($E$4,$C$4,1))+1<=DAY(EOMONTH(DATE($E$4,$C$4,1),0))),35-WEEKDAY(DATE($E$4,$C$4,1))+1,"") -> 31
A38: =IF(AND(36-WEEKDAY(DATE($E$4,$C$4,1))+1>=1,36-WEEKDAY(DATE($E$4,$C$4,1))+1<=DAY(EOMONTH(DATE($E$4,$C$4,1),0))),36-WEEKDAY(DATE($E$4,$C$4,1))+1,"") | C38: =IF(AND(37-WEEKDAY(DATE($E$4,$C$4,1))+1>=1,37-WEEKDAY(DATE($E$4,$C$4,1))+1<=DAY(EOMONTH(DATE($E$4,$C$4,1),0))),37-WEEKDAY(DATE($E$4,$C$4,1))+1,"") | E38: =IF(AND(38-WEEKDAY(DATE($E$4,$C$4,1))+1>=1,38-WEEKDAY(DATE($E$4,$C$4,1))+1<=DAY(EOMONTH(DATE($E$4,$C$4,1),0))),38-WEEKDAY(DATE($E$4,$C$4,1))+1,"") | G38: =IF(AND(39-WEEKDAY(DATE($E$4,$C$4,1))+1>=1,39-WEEKDAY(DATE($E$4,$C$4,1))+1<=DAY(EOMONTH(DATE($E$4,$C$4,1),0))),39-WEEKDAY(DATE($E$4,$C$4,1))+1,"") | I38: =IF(AND(40-WEEKDAY(DATE($E$4,$C$4,1))+1>=1,40-WEEKDAY(DATE($E$4,$C$4,1))+1<=DAY(EOMONTH(DATE($E$4,$C$4,1),0))),40-WEEKDAY(DATE($E$4,$C$4,1))+1,"") | K38: =IF(AND(41-WEEKDAY(DATE($E$4,$C$4,1))+1>=1,41-WEEKDAY(DATE($E$4,$C$4,1))+1<=DAY(EOMONTH(DATE($E$4,$C$4,1),0))),41-WEEKDAY(DATE($E$4,$C$4,1))+1,"") | M38: =IF(AND(42-WEEKDAY(DATE($E$4,$C$4,1))+1>=1,42-WEEKDAY(DATE($E$4,$C$4,1))+1<=DAY(EOMONTH(DATE($E$4,$C$4,1),0))),42-WEEKDAY(DATE($E$4,$C$4,1))+1,"")
A45: 📝 How to Use | I45: ✓ | J45: =done -> #NAME? | L45: =pending -> #NAME?
A46: • Type tasks directly in Task column • Click ✓ to mark complete • Pending tasks appear in 'Pending Tasks' sheet

Sheet _Helper
A2: =IF(AND(Calendar!A9<>"✓",Calendar!B9<>"",Calendar!A8<>""),Calendar!B9,"") | B2: =IF(A2<>"",DATE(Calendar!$E$4,Calendar!$C$4,Calendar!A8),"") | C2: =IF(A2<>"",TEXT(B2,"dddd"),"") | D2: =IF(A2<>"",1,"") | E2: =IF(A2<>"",SUMPRODUCT(($A$2:$A2<>"")*1),"")
A3: =IF(AND(Calendar!A10<>"✓",Calendar!B10<>"",Calendar!A8<>""),Calendar!B10,"") | B3: =IF(A3<>"",DATE(Calendar!$E$4,Calendar!$C$4,Calendar!A8),"") | C3: =IF(A3<>"",TEXT(B3,"dddd"),"") | D3: =IF(A3<>"",1,"") | E3: =IF(A3<>"",SUMPRODUCT(($A$2:$A3<>"")*1),"")
A4: =IF(AND(Calendar!A11<>"✓",Calendar!B11<>"",Calendar!A8<>""),Calendar!B11,"") | B4: =IF(A4<>"",DATE(Calendar!$E$4,Calendar!$C$4,Calendar!A8),"") | C4: =IF(A4<>"",TEXT(B4,"dddd"),"") | D4: =IF(A4<>"",1,"") | E4: =IF(A4<>"",SUMPRODUCT(($A$2:$A4<>"")*1),"")
A5: =IF(AND(Calendar!A12<>"✓",Calendar!B12<>"",Calendar!A8<>""),Calendar!B12,"") | B5: =IF(A5<>"",DATE(Calendar!$E$4,Calendar!$C$4,Calendar!A8),"") | C5: =IF(A5<>"",TEXT(B5,"dddd"),"") | D5: =IF(A5<>"",1,"") | E5: =IF(A5<>"",SUMPRODUCT(($A$2:$A5<>"")*1),"")
A6: =IF(AND(Calendar!A13<>"✓",Calendar!B13<>"",Calendar!A8<>""),Calendar!B13,"") | B6: =IF(A6<>"",DATE(Calendar!$E$4,Calendar!$C$4,Calendar!A8),"") | C6: =IF(A6<>"",TEXT(B6,"dddd"),"") | D6: =IF(A6<>"",1,"") | E6: =IF(A6<>"",SUMPRODUCT(($A$2:$A6<>"")*1),"")
A7: =IF(AND(Calendar!C9<>"✓",Calendar!D9<>"",Calendar!C8<>""),Calendar!D9,"") | B7: =IF(A7<>"",DATE(Calendar!$E$4,Calendar!$C$4,Calendar!C8),"") | C7: =IF(A7<>"",TEXT(B7,"dddd"),"") | D7: =IF(A7<>"",1,"") | E7: =IF(A7<>"",SUMPRODUCT(($A$2:$A7<>"")*1),"")
A8: =IF(AND(Calendar!C10<>"✓",Calendar!D10<>"",Calendar!C8<>""),Calendar!D10,"") | B8: =IF(A8<>"",DATE(Calendar!$E$4,Calendar!$C$4,Calendar!C8),"") | C8: =IF(A8<>"",TEXT(B8,"dddd"),"") | D8: =IF(A8<>"",1,"") | E8: =IF(A8<>"",SUMPRODUCT(($A$2:$A8<>"")*1),"")
A9: =IF(AND(Calendar!C11<>"✓",Calendar!D11<>"",Calendar!C8<>""),Calendar!D11,"") | B9: =IF(A9<>"",DATE(Calendar!$E$4,Calendar!$C$4,Calendar!C8),"") | C9: =IF(A9<>"",TEXT(B9,"dddd"),"") | D9: =IF(A9<>"",1,"") | E9: =IF(A9<>"",SUMPRODUCT(($A$2:$A9<>"")*1),"")
A10: =IF(AND(Calendar!C12<>"✓",Calendar!D12<>"",Calendar!C8<>""),Calendar!D12,"") | B10: =IF(A10<>"",DATE(Calendar!$E$4,Calendar!$C$4,Calendar!C8),"") | C10: =IF(A10<>"",TEXT(B10,"dddd"),"") | D10: =IF(A10<>"",1,"") | E10: =IF(A10<>"",SUMPRODUCT(($A$2:$A10<>"")*1),"")
A11: =IF(AND(Calendar!C13<>"✓",Calendar!D13<>"",Calendar!C8<>""),Calendar!D13,"") | B11: =IF(A11<>"",DATE(Calendar!$E$4,Calendar!$C$4,Calendar!C8),"") | C11: =IF(A11<>"",TEXT(B11,"dddd"),"") | D11: =IF(A11<>"",1,"") | E11: =IF(A11<>"",SUMPRODUCT(($A$2:$A11<>"")*1),"")
A12: =IF(AND(Calendar!E9<>"✓",Calendar!F9<>"",Calendar!E8<>""),Calendar!F9,"") | B12: =IF(A12<>"",DATE(Calendar!$E$4,Calendar!$C$4,Calendar!E8),"") | C12: =IF(A12<>"",TEXT(B12,"dddd"),"") | D12: =IF(A12<>"",1,"") | E12: =IF(A12<>"",SUMPRODUCT(($A$2:$A12<>"")*1),"")
A13: =IF(AND(Calendar!E10<>"✓",Calendar!F10<>"",Calendar!E8<>""),Calendar!F10,"") | B13: =IF(A13<>"",DATE(Calendar!$E$4,Calendar!$C$4,Calendar!E8),"") | C13: =IF(A13<>"",TEXT(B13,"dddd"),"") | D13: =IF(A13<>"",1,"") | E13: =IF(A13<>"",SUMPRODUCT(($A$2:$A13<>"")*1),"")
A14: =IF(AND(Calendar!E11<>"✓",Calendar!F11<>"",Calendar!E8<>""),Calendar!F11,"") | B14: =IF(A14<>"",DATE(Calendar!$E$4,Calendar!$C$4,Calendar!E8),"") | C14: =IF(A14<>"",TEXT(B14,"dddd"),"") | D14: =IF(A14<>"",1,"") | E14: =IF(A14<>"",SUMPRODUCT(($A$2:$A14<>"")*1),"")
A15: =IF(AND(Calendar!E12<>"✓",Calendar!F12<>"",Calendar!E8<>""),Calendar!F12,"") | B15: =IF(A15<>"",DATE(Calendar!$E$4,Calendar!$C$4,Calendar!E8),"") | C15: =IF(A15<>"",TEXT(B15,"dddd"),"") | D15: =IF(A15<>"",1,"") | E15: =IF(A15<>"",SUMPRODUCT(($A$2:$A15<>"")*1),"")
A16: =IF(AND(Calendar!E13<>"✓",Calendar!F13<>"",Calendar!E8<>""),Calendar!F13,"") | B16: =IF(A16<>"",DATE(Calendar!$E$4,Calendar!$C$4,Calendar!E8),"") | C16: =IF(A16<>"",TEXT(B16,"dddd"),"") | D16: =IF(A16<>"",1,"") | E16: =IF(A16<>"",SUMPRODUCT(($A$2:$A16<>"")*1),"")
A17: =IF(AND(Calendar!G9<>"✓",Calendar!H9<>"",Calendar!G8<>""),Calendar!H9,"") | B17: =IF(A17<>"",DATE(Calendar!$E$4,Calendar!$C$4,Calendar!G8),"") | C17: =IF(A17<>"",TEXT(B17,"dddd"),"") | D17: =IF(A17<>"",1,"") | E17: =IF(A17<>"",SUMPRODUCT(($A$2:$A17<>"")*1),"")
A18: =IF(AND(Calendar!G10<>"✓",Calendar!H10<>"",Calendar!G8<>""),Calendar!H10,"") | B18: =IF(A18<>"",DATE(Calendar!$E$4,Calendar!$C$4,Calendar!G8),"") | C18: =IF(A18<>"",TEXT(B18,"dddd"),"") | D18: =IF(A18<>"",1,"") | E18: =IF(A18<>"",SUMPRODUCT(($A$2:$A18<>"")*1),"")
A19: =IF(AND(Calendar!G11<>"✓",Calendar!H11<>"",Calendar!G8<>""),Calendar!H11,"") | B19: =IF(A19<>"",DATE(Calendar!$E$4,Calendar!$C$4,Calendar!G8),"") | C19: =IF(A19<>"",TEXT(B19,"dddd"),"") | D19: =IF(A19<>"",1,"") | E19: =IF(A19<>"",SUMPRODUCT(($A$2:$A19<>"")*1),"")
A20: =IF(AND(Calendar!G12<>"✓",Calendar!H12<>"",Calendar!G8<>""),Calendar!H12,"") | B20: =IF(A20<>"",DATE(Calendar!$E$4,Calendar!$C$4,Calendar!G8),"") | C20: =IF(A20<>"",TEXT(B20,"dddd"),"") | D20: =IF(A20<>"",1,"") | E20: =IF(A20<>"",SUMPRODUCT(($A$2:$A20<>"")*1),"")
A21: =IF(AND(Calendar!G13<>"✓",Calendar!H13<>"",Calendar!G8<>""),Calendar!H13,"") | B21: =IF(A21<>"",DATE(Calendar!$E$4,Calendar!$C$4,Calendar!G8),"") | C21: =IF(A21<>"",TEXT(B21,"dddd"),"") | D21: =IF(A21<>"",1,"") | E21: =IF(A21<>"",SUMPRODUCT(($A$2:$A21<>"")*1),"")
A22: =IF(AND(Calendar!I9<>"✓",Calendar!J9<>"",Calendar!I8<>""),Calendar!J9,"") -> Sprint planning | B22: =IF(A22<>"",DATE(Calendar!$E$4,Calendar!$C$4,Calendar!I8),"") -> 46023 | C22: =IF(A22<>"",TEXT(B22,"dddd"),"") -> Thursday | D22: =IF(A22<>"",1,"") -> 1 | E22: =IF(A22<>"",SUMPRODUCT(($A$2:$A22<>"")*1),"") -> 1
A23: =IF(AND(Calendar!I10<>"✓",Calendar!J10<>"",Calendar!I8<>""),Calendar!J10,"") | B23: =IF(A23<>"",DATE(Calendar!$E$4,Calendar!$C$4,Calendar!I8),"") | C23: =IF(A23<>"",TEXT(B23,"dddd"),"") | D23: =IF(A23<>"",1,"") | E23: =IF(A23<>"",SUMPRODUCT(($A$2:$A23<>"")*1),"")
A24: =IF(AND(Calendar!I11<>"✓",Calendar!J11<>"",Calendar!I8<>""),Calendar!J11,"") | B24: =IF(A24<>"",DATE(Calendar!$E$4,Calendar!$C$4,Calendar!I8),"") | C24: =IF(A24<>"",TEXT(B24,"dddd"),"") | D24: =IF(A24<>"",1,"") | E24: =IF(A24<>"",SUMPRODUCT(($A$2:$A24<>"")*1),"")
A25: =IF(AND(Calendar!I12<>"✓",Calendar!J12<>"",Calendar!I8<>""),Calendar!J12,"") | B25: =IF(A25<>"",DATE(Calendar!$E$4,Calendar!$C$4,Calendar!I8),"") | C25: =IF(A25<>"",TEXT(B25,"dddd"),"") | D25: =IF(A25<>"",1,"") | E25: =IF(A25<>"",SUMPRODUCT(($A$2:$A25<>"")*1),"")
A26: =IF(AND(Calendar!I13<>"✓",Calendar!J13<>"",Calendar!I8<>""),Calendar!J13,"") | B26: =IF(A26<>"",DATE(Calendar!$E$4,Calendar!$C$4,Calendar!I8),"") | C26: =IF(A26<>"",TEXT(B26,"dddd"),"") | D26: =IF(A26<>"",1,"") | E26: =IF(A26<>"",SUMPRODUCT(($A$2:$A26<>"")*1),"")
A27: =IF(AND(Calendar!K9<>"✓",Calendar!L9<>"",Calendar!K8<>""),Calendar!L9,"") | B27: =IF(A27<>"",DATE(Calendar!$E$4,Calendar!$C$4,Calendar!K8),"") | C27: =IF(A27<>"",TEXT(B27,"dddd"),"") | D27: =IF(A27<>"",1,"") | E27: =IF(A27<>"",SUMPRODUCT(($A$2:$A27<>"")*1),"")
A28: =IF(AND(Calendar!K10<>"✓",Calendar!L10<>"",Calendar!K8<>""),Calendar!L10,"") | B28: =IF(A28<>"",DATE(Calendar!$E$4,Calendar!$C$4,Calendar!K8),"") | C28: =IF(A28<>"",TEXT(B28,"dddd"),"") | D28: =IF(A28<>"",1,"") | E28: =IF(A28<>"",SUMPRODUCT(($A$2:$A28<>"")*1),"")
A29: =IF(AND(Calendar!K11<>"✓",Calendar!L11<>"",Calendar!K8<>""),Calendar!L11,"") | B29: =IF(A29<>"",DATE(Calendar!$E$4,Calendar!$C$4,Calendar!K8),"") | C29: =IF(A29<>"",TEXT(B29,"dddd"),"") | D29: =IF(A29<>"",1,"") | E29: =IF(A29<>"",SUMPRODUCT(($A$2:$A29<>"")*1),"")
A30: =IF(AND(Calendar!K12<>"✓",Calendar!L12<>"",Calendar!K8<>""),Calendar!L12,"") | B30: =IF(A30<>"",DATE(Calendar!$E$4,Calendar!$C$4,Calendar!K8),"") | C30: =IF(A30<>"",TEXT(B30,"dddd"),"") | D30: =IF(A30<>"",1,"") | E30: =IF(A30<>"",SUMPRODUCT(($A$2:$A30<>"")*1),"")
A31: =IF(AND(Calendar!K13<>"✓",Calendar!L13<>"",Calendar!K8<>""),Calendar!L13,"") | B31: =IF(A31<>"",DATE(Calendar!$E$4,Calendar!$C$4,Calendar!K8),"") | C31: =IF(A31<>"",TEXT(B31,"dddd"),"") | D31: =IF(A31<>"",1,"") | E31: =IF(A31<>"",SUMPRODUCT(($A$2:$A31<>"")*1),"")
A32: =IF(AND(Calendar!M9<>"✓",Calendar!N9<>"",Calendar!M8<>""),Calendar!N9,"") | B32: =IF(A32<>"",DATE(Calendar!$E$4,Calendar!$C$4,Calendar!M8),"") | C32: =IF(A32<>"",TEXT(B32,"dddd"),"") | D32: =IF(A32<>"",1,"") | E32: =IF(A32<>"",SUMPRODUCT(($A$2:$A32<>"")*1),"")
A33: =IF(AND(Calendar!M10<>"✓",Calendar!N10<>"",Calendar!M8<>""),Calendar!N10,"") | B33: =IF(A33<>"",DATE(Calendar!$E$4,Calendar!$C$4,Calendar!M8),"") | C33: =IF(A33<>"",TEXT(B33,"dddd"),"") | D33: =IF(A33<>"",1,"") | E33: =IF(A33<>"",SUMPRODUCT(($A$2:$A33<>"")*1),"")
A34: =IF(AND(Calendar!M11<>"✓",Calendar!N11<>"",Calendar!M8<>""),Calendar!N11,"") | B34: =IF(A34<>"",DATE(Calendar!$E$4,Calendar!$C$4,Calendar!M8),"") | C34: =IF(A34<>"",TEXT(B34,"dddd"),"") | D34: =IF(A34<>"",1,"") | E34: =IF(A34<>"",SUMPRODUCT(($A$2:$A34<>"")*1),"")
A35: =IF(AND(Calendar!M12<>"✓",Calendar!N12<>"",Calendar!M8<>""),Calendar!N12,"") | B35: =IF(A35<>"",DATE(Calendar!$E$4,Calendar!$C$4,Calendar!M8),"") | C35: =IF(A35<>"",TEXT(B35,"dddd"),"") | D35: =IF(A35<>"",1,"") | E35: =IF(A35<>"",SUMPRODUCT(($A$2:$A35<>"")*1),"")
A36: =IF(AND(Calendar!M13<>"✓",Calendar!N13<>"",Calendar!M8<>""),Calendar!N13,"") | B36: =IF(A36<>"",DATE(Calendar!$E$4,Calendar!$C$4,Calendar!M8),"") | C36: =IF(A36<>"",TEXT(B36,"dddd"),"") | D36: =IF(A36<>"",1,"") | E36: =IF(A36<>"",SUMPRODUCT(($A$2:$A36<>"")*1),"")
A37: =IF(AND(Calendar!A15<>"✓",Calendar!B15<>"",Calendar!A14<>""),Calendar!B15,"") | B37: =IF(A37<>"",DATE(Calendar!$E$4,Calendar!$C$4,Calendar!A14),"") | C37: =IF(A37<>"",TEXT(B37,"dddd"),"") | D37: =IF(A37<>"",2,"") | E37: =IF(A37<>"",SUMPRODUCT(($A$2:$A37<>"")*1),"")
A38: =IF(AND(Calendar!A16<>"✓",Calendar!B16<>"",Calendar!A14<>""),Calendar!B16,"") | B38: =IF(A38<>"",DATE(Calendar!$E$4,Calendar!$C$4,Calendar!A14),"") | C38: =IF(A38<>"",TEXT(B38,"dddd"),"") | D38: =IF(A38<>"",2,"") | E38: =IF(A38<>"",SUMPRODUCT(($A$2:$A38<>"")*1),"")
A39: =IF(AND(Calendar!A17<>"✓",Calendar!B17<>"",Calendar!A14<>""),Calendar!B17,"") | B39: =IF(A39<>"",DATE(Calendar!$E$4,Calendar!$C$4,Calendar!A14),"") | C39: =IF(A39<>"",TEXT(B39,"dddd"),"") | D39: =IF(A39<>"",2,"") | E39: =IF(A39<>"",SUMPRODUCT(($A$2:$A39<>"")*1),"")
A40: =IF(AND(Calendar!A18<>"✓",Calendar!B18<>"",Calendar!A14<>""),Calendar!B18,"") | B40: =IF(A40<>"",DATE(Calendar!$E$4,Calendar!$C$4,Calendar!A14),"") | C40: =IF(A40<>"",TEXT(B40,"dddd"),"") | D40: =IF(A40<>"",2,"") | E40: =IF(A40<>"",SUMPRODUCT(($A$2:$A40<>"")*1),"")
A41: =IF(AND(Calendar!A19<>"✓",Calendar!B19<>"",Calendar!A14<>""),Calendar!B19,"") | B41: =IF(A41<>"",DATE(Calendar!$E$4,Calendar!$C$4,Calendar!A14),"") | C41: =IF(A41<>"",TEXT(B41,"dddd"),"") | D41: =IF(A41<>"",2,"") | E41: =IF(A41<>"",SUMPRODUCT(($A$2:$A41<>"")*1),"")
...

Sheet Pending Tasks
A1: 📋 PENDING TASKS
A4: ⚡ Auto-updated from Calendar - shows only unchecked tasks | D4: Total Pending: | E4: =SUMPRODUCT((_Helper!A2:A212<>"")*1) -> 9
A6: # | B6: Date | C6: Day | D6: Task | E6: Week
A7: =IFERROR(IF(MATCH(1,_Helper!$E$2:$E$212,0)>0,1,""),"") -> 1 | B7: =IFERROR(INDEX(_Helper!$B$2:$B$212,MATCH(1,_Helper!$E$2:$E$212,0)),"") -> 46023 | C7: =IFERROR(INDEX(_Helper!$C$2:$C$212,MATCH(1,_Helper!$E$2:$E$212,0)),"") -> Thursday | D7: =IFERROR(INDEX(_Helper!$A$2:$A$212,MATCH(1,_Helper!$E$2:$E$212,0)),"") -> Sprint planning | E7: =IFERROR(INDEX(_Helper!$D$2:$D$212,MATCH(1,_Helper!$E$2:$E$212,0)),"") -> 1
A8: =IFERROR(IF(MATCH(2,_Helper!$E$2:$E$212,0)>0,2,""),"") -> 2 | B8: =IFERROR(INDEX(_Helper!$B$2:$B$212,MATCH(2,_Helper!$E$2:$E$212,0)),"") -> 46027 | C8: =IFERROR(INDEX(_Helper!$C$2:$C$212,MATCH(2,_Helper!$E$2:$E$212,0)),"") -> Monday | D8: =IFERROR(INDEX(_Helper!$A$2:$A$212,MATCH(2,_Helper!$E$2:$E$212,0)),"") -> Process mining workshop | E8: =IFERROR(INDEX(_Helper!$D$2:$D$212,MATCH(2,_Helper!$E$2:$E$212,0)),"") -> 2
A9: =IFERROR(IF(MATCH(3,_Helper!$E$2:$E$212,0)>0,3,""),"") -> 3 | B9: =IFERROR(INDEX(_Helper!$B$2:$B$212,MATCH(3,_Helper!$E$2:$E$212,0)),"") -> 46027 | C9: =IFERROR(INDEX(_Helper!$C$2:$C$212,MATCH(3,_Helper!$E$2:$E$212,0)),"") -> Monday | D9: =IFERROR(INDEX(_Helper!$A$2:$A$212,MATCH(3,_Helper!$E$2:$E$212,0)),"") -> Data extraction | E9: =IFERROR(INDEX(_Helper!$D$2:$D$212,MATCH(3,_Helper!$E$2:$E$212,0)),"") -> 2
A10: =IFERROR(IF(MATCH(4,_Helper!$E$2:$E$212,0)>0,4,""),"") -> 4 | B10: =IFERROR(INDEX(_Helper!$B$2:$B$212,MATCH(4,_Helper!$E$2:$E$212,0)),"") -> 46029 | C10: =IFERROR(INDEX(_Helper!$C$2:$C$212,MATCH(4,_Helper!$E$2:$E$212,0)),"") -> Wednesday | D10: =IFERROR(INDEX(_Helper!$A$2:$A$212,MATCH(4,_Helper!$E$2:$E$212,0)),"") -> Client presentation | E10: =IFERROR(INDEX(_Helper!$D$2:$D$212,MATCH(4,_Helper!$E$2:$E$212,0)),"") -> 2
A11: =IFERROR(IF(MATCH(5,_Helper!$E$2:$E$212,0)>0,5,""),"") -> 5 | B11: =IFERROR(INDEX(_Helper!$B$2:$B$212,MATCH(5,_Helper!$E$2:$E$212,0)),"") -> 46030 | C11: =IFERROR(INDEX(_Helper!$C$2:$C$212,MATCH(5,_Helper!$E$2:$E$212,0)),"") -> Thursday | D11: =IFERROR(INDEX(_Helper!$A$2:$A$212,MATCH(5,_Helper!$E$2:$E$212,0)),"") -> Documentation update | E11: =IFERROR(INDEX(_Helper!$D$2:$D$212,MATCH(5,_Helper!$E$2:$E$212,0)),"") -> 2
A12: =IFERROR(IF(MATCH(6,_Helper!$E$2:$E$212,0)>0,6,""),"") -> 6 | B12: =IFERROR(INDEX(_Helper!$B$2:$B$212,MATCH(6,_Helper!$E$2:$E$212,0)),"") -> 46033 | C12: =IFERROR(INDEX(_Helper!$C$2:$C$212,MATCH(6,_Helper!$E$2:$E$212,0)),"") -> Sunday | D12: =IFERROR(INDEX(_Helper!$A$2:$A$212,MATCH(6,_Helper!$E$2:$E$212,0)),"") -> Weekly report | E12: =IFERROR(INDEX(_Helper!$D$2:$D$212,MATCH(6,_Helper!$E$2:$E$212,0)),"") -> 3
A13: =IFERROR(IF(MATCH(7,_Helper!$E$2:$E$212,0)>0,7,""),"") -> 7 | B13: =IFERROR(INDEX(_Helper!$B$2:$B$212,MATCH(7,_Helper!$E$2:$E$212,0)),"") -> 46034 | C13: =IFERROR(INDEX(_Helper!$C$2:$C$212,MATCH(7,_Helper!$E$2:$E$212,0)),"") -> Monday | D13: =IFERROR(INDEX(_Helper!$A$2:$A$212,MATCH(7,_Helper!$E$2:$E$212,0)),"") -> Code refactoring | E13: =IFERROR(INDEX(_Helper!$D$2:$D$212,MATCH(7,_Helper!$E$2:$E$212,0)),"") -> 3
A14: =IFERROR(IF(MATCH(8,_Helper!$E$2:$E$212,0)>0,8,""),"") -> 8 | B14: =IFERROR(INDEX(_Helper!$B$2:$B$212,MATCH(8,_Helper!$E$2:$E$212,0)),"") -> 46035 | C14: =IFERROR(INDEX(_Helper!$C$2:$C$212,MATCH(8,_Helper!$E$2:$E$212,0)),"") -> Tuesday | D14: =IFERROR(INDEX(_Helper!$A$2:$A$212,MATCH(8,_Helper!$E$2:$E$212,0)),"") -> Testing session | E14: =IFERROR(INDEX(_Helper!$D$2:$D$212,MATCH(8,_Helper!$E$2:$E$212,0)),"") -> 3
A15: =IFERROR(IF(MATCH(9,_Helper!$E$2:$E$212,0)>0,9,""),"") -> 9 | B15: =IFERROR(INDEX(_Helper!$B$2:$B$212,MATCH(9,_Helper!$E$2:$E$212,0)),"") -> 46036 | C15: =IFERROR(INDEX(_Helper!$C$2:$C$212,MATCH(9,_Helper!$E$2:$E$212,0)),"") -> Wednesday | D15: =IFERROR(INDEX(_Helper!$A$2:$A$212,MATCH(9,_Helper!$E$2:$E$212,0)),"") -> Deployment prep | E15: =IFERROR(INDEX(_Helper!$D$2:$D$212,MATCH(9,_Helper!$E$2:$E$212,0)),"") -> 3
A16: =IFERROR(IF(MATCH(10,_Helper!$E$2:$E$212,0)>0,10,""),"") | B16: =IFERROR(INDEX(_Helper!$B$2:$B$212,MATCH(10,_Helper!$E$2:$E$212,0)),"") | C16: =IFERROR(INDEX(_Helper!$C$2:$C$212,MATCH(10,_Helper!$E$2:$E$212,0)),"") | D16: =IFERROR(INDEX(_Helper!$A$2:$A$212,MATCH(10,_Helper!$E$2:$E$212,0)),"") | E16: =IFERROR(INDEX(_Helper!$D$2:$D$212,MATCH(10,_Helper!$E$2:$E$212,0)),"")
A17: =IFERROR(IF(MATCH(11,_Helper!$E$2:$E$212,0)>0,11,""),"") | B17: =IFERROR(INDEX(_Helper!$B$2:$B$212,MATCH(11,_Helper!$E$2:$E$212,0)),"") | C17: =IFERROR(INDEX(_Helper!$C$2:$C$212,MATCH(11,_Helper!$E$2:$E$212,0)),"") | D17: =IFERROR(INDEX(_Helper!$A$2:$A$212,MATCH(11,_Helper!$E$2:$E$212,0)),"") | E17: =IFERROR(INDEX(_Helper!$D$2:$D$212,MATCH(11,_Helper!$E$2:$E$212,0)),"")
A18: =IFERROR(IF(MATCH(12,_Helper!$E$2:$E$212,0)>0,12,""),"") | B18: =IFERROR(INDEX(_Helper!$B$2:$B$212,MATCH(12,_Helper!$E$2:$E$212,0)),"") | C18: =IFERROR(INDEX(_Helper!$C$2:$C$212,MATCH(12,_Helper!$E$2:$E$212,0)),"") | D18: =IFERROR(INDEX(_Helper!$A$2:$A$212,MATCH(12,_Helper!$E$2:$E$212,0)),"") | E18: =IFERROR(INDEX(_Helper!$D$2:$D$212,MATCH(12,_Helper!$E$2:$E$212,0)),"")
A19: =IFERROR(IF(MATCH(13,_Helper!$E$2:$E$212,0)>0,13,""),"") | B19: =IFERROR(INDEX(_Helper!$B$2:$B$212,MATCH(13,_Helper!$E$2:$E$212,0)),"") | C19: =IFERROR(INDEX(_Helper!$C$2:$C$212,MATCH(13,_Helper!$E$2:$E$212,0)),"") | D19: =IFERROR(INDEX(_Helper!$A$2:$A$212,MATCH(13,_Helper!$E$2:$E$212,0)),"") | E19: =IFERROR(INDEX(_Helper!$D$2:$D$212,MATCH(13,_Helper!$E$2:$E$212,0)),"")
A20: =IFERROR(IF(MATCH(14,_Helper!$E$2:$E$212,0)>0,14,""),"") | B20: =IFERROR(INDEX(_Helper!$B$2:$B$212,MATCH(14,_Helper!$E$2:$E$212,0)),"") | C20: =IFERROR(INDEX(_Helper!$C$2:$C$212,MATCH(14,_Helper!$E$2:$E$212,0)),"") | D20: =IFERROR(INDEX(_Helper!$A$2:$A$212,MATCH(14,_Helper!$E$2:$E$212,0)),"") | E20: =IFERROR(INDEX(_Helper!$D$2:$D$212,MATCH(14,_Helper!$E$2:$E$212,0)),"")
A21: =IFERROR(IF(MATCH(15,_Helper!$E$2:$E$212,0)>0,15,""),"") | B21: =IFERROR(INDEX(_Helper!$B$2:$B$212,MATCH(15,_Helper!$E$2:$E$212,0)),"") | C21: =IFERROR(INDEX(_Helper!$C$2:$C$212,MATCH(15,_Helper!$E$2:$E$212,0)),"") | D21: =IFERROR(INDEX(_Helper!$A$2:$A$212,MATCH(15,_Helper!$E$2:$E$212,0)),"") | E21: =IFERROR(INDEX(_Helper!$D$2:$D$212,MATCH(15,_Helper!$E$2:$E$212,0)),"")
A22: =IFERROR(IF(MATCH(16,_Helper!$E$2:$E$212,0)>0,16,""),"") | B22: =IFERROR(INDEX(_Helper!$B$2:$B$212,MATCH(16,_Helper!$E$2:$E$212,0)),"") | C22: =IFERROR(INDEX(_Helper!$C$2:$C$212,MATCH(16,_Helper!$E$2:$E$212,0)),"") | D22: =IFERROR(INDEX(_Helper!$A$2:$A$212,MATCH(16,_Helper!$E$2:$E$212,0)),"") | E22: =IFERROR(INDEX(_Helper!$D$2:$D$212,MATCH(16,_Helper!$E$2:$E$212,0)),"")
A23: =IFERROR(IF(MATCH(17,_Helper!$E$2:$E$212,0)>0,17,""),"") | B23: =IFERROR(INDEX(_Helper!$B$2:$B$212,MATCH(17,_Helper!$E$2:$E$212,0)),"") | C23: =IFERROR(INDEX(_Helper!$C$2:$C$212,MATCH(17,_Helper!$E$2:$E$212,0)),"") | D23: =IFERROR(INDEX(_Helper!$A$2:$A$212,MATCH(17,_Helper!$E$2:$E$212,0)),"") | E23: =IFERROR(INDEX(_Helper!$D$2:$D$212,MATCH(17,_Helper!$E$2:$E$212,0)),"")
A24: =IFERROR(IF(MATCH(18,_Helper!$E$2:$E$212,0)>0,18,""),"") | B24: =IFERROR(INDEX(_Helper!$B$2:$B$212,MATCH(18,_Helper!$E$2:$E$212,0)),"") | C24: =IFERROR(INDEX(_Helper!$C$2:$C$212,MATCH(18,_Helper!$E$2:$E$212,0)),"") | D24: =IFERROR(INDEX(_Helper!$A$2:$A$212,MATCH(18,_Helper!$E$2:$E$212,0)),"") | E24: =IFERROR(INDEX(_Helper!$D$2:$D$212,MATCH(18,_Helper!$E$2:$E$212,0)),"")
A25: =IFERROR(IF(MATCH(19,_Helper!$E$2:$E$212,0)>0,19,""),"") | B25: =IFERROR(INDEX(_Helper!$B$2:$B$212,MATCH(19,_Helper!$E$2:$E$212,0)),"") | C25: =IFERROR(INDEX(_Helper!$C$2:$C$212,MATCH(19,_Helper!$E$2:$E$212,0)),"") | D25: =IFERROR(INDEX(_Helper!$A$2:$A$212,MATCH(19,_Helper!$E$2:$E$212,0)),"") | E25: =IFERROR(INDEX(_Helper!$D$2:$D$212,MATCH(19,_Helper!$E$2:$E$212,0)),"")
A26: =IFERROR(IF(MATCH(20,_Helper!$E$2:$E$212,0)>0,20,""),"") | B26: =IFERROR(INDEX(_Helper!$B$2:$B$212,MATCH(20,_Helper!$E$2:$E$212,0)),"") | C26: =IFERROR(INDEX(_Helper!$C$2:$C$212,MATCH(20,_Helper!$E$2:$E$212,0)),"") | D26: =IFERROR(INDEX(_Helper!$A$2:$A$212,MATCH(20,_Helper!$E$2:$E$212,0)),"") | E26: =IFERROR(INDEX(_Helper!$D$2:$D$212,MATCH(20,_Helper!$E$2:$E$212,0)),"")
A27: =IFERROR(IF(MATCH(21,_Helper!$E$2:$E$212,0)>0,21,""),"") | B27: =IFERROR(INDEX(_Helper!$B$2:$B$212,MATCH(21,_Helper!$E$2:$E$212,0)),"") | C27: =IFERROR(INDEX(_Helper!$C$2:$C$212,MATCH(21,_Helper!$E$2:$E$212,0)),"") | D27: =IFERROR(INDEX(_Helper!$A$2:$A$212,MATCH(21,_Helper!$E$2:$E$212,0)),"") | E27: =IFERROR(INDEX(_Helper!$D$2:$D$212,MATCH(21,_Helper!$E$2:$E$212,0)),"")
A28: =IFERROR(IF(MATCH(22,_Helper!$E$2:$E$212,0)>0,22,""),"") | B28: =IFERROR(INDEX(_Helper!$B$2:$B$212,MATCH(22,_Helper!$E$2:$E$212,0)),"") | C28: =IFERROR(INDEX(_Helper!$C$2:$C$212,MATCH(22,_Helper!$E$2:$E$212,0)),"") | D28: =IFERROR(INDEX(_Helper!$A$2:$A$212,MATCH(22,_Helper!$E$2:$E$212,0)),"") | E28: =IFERROR(INDEX(_Helper!$D$2:$D$212,MATCH(22,_Helper!$E$2:$E$212,0)),"")
A29: =IFERROR(IF(MATCH(23,_Helper!$E$2:$E$212,0)>0,23,""),"") | B29: =IFERROR(INDEX(_Helper!$B$2:$B$212,MATCH(23,_Helper!$E$2:$E$212,0)),"") | C29: =IFERROR(INDEX(_Helper!$C$2:$C$212,MATCH(23,_Helper!$E$2:$E$212,0)),"") | D29: =IFERROR(INDEX(_Helper!$A$2:$A$212,MATCH(23,_Helper!$E$2:$E$212,0)),"") | E29: =IFERROR(INDEX(_Helper!$D$2:$D$212,MATCH(23,_Helper!$E$2:$E$212,0)),"")
A30: =IFERROR(IF(MATCH(24,_Helper!$E$2:$E$212,0)>0,24,""),"") | B30: =IFERROR(INDEX(_Helper!$B$2:$B$212,MATCH(24,_Helper!$E$2:$E$212,0)),"") | C30: =IFERROR(INDEX(_Helper!$C$2:$C$212,MATCH(24,_Helper!$E$2:$E$212,0)),"") | D30: =IFERROR(INDEX(_Helper!$A$2:$A$212,MATCH(24,_Helper!$E$2:$E$212,0)),"") | E30: =IFERROR(INDEX(_Helper!$D$2:$D$212,MATCH(24,_Helper!$E$2:$E$212,0)),"")
A31: =IFERROR(IF(MATCH(25,_Helper!$E$2:$E$212,0)>0,25,""),"") | B31: =IFERROR(INDEX(_Helper!$B$2:$B$212,MATCH(25,_Helper!$E$2:$E$212,0)),"") | C31: =IFERROR(INDEX(_Helper!$C$2:$C$212,MATCH(25,_Helper!$E$2:$E$212,0)),"") | D31: =IFERROR(INDEX(_Helper!$A$2:$A$212,MATCH(25,_Helper!$E$2:$E$212,0)),"") | E31: =IFERROR(INDEX(_Helper!$D$2:$D$212,MATCH(25,_Helper!$E$2:$E$212,0)),"")
A32: =IFERROR(IF(MATCH(26,_Helper!$E$2:$E$212,0)>0,26,""),"") | B32: =IFERROR(INDEX(_Helper!$B$2:$B$212,MATCH(26,_Helper!$E$2:$E$212,0)),"") | C32: =IFERROR(INDEX(_Helper!$C$2:$C$212,MATCH(26,_Helper!$E$2:$E$212,0)),"") | D32: =IFERROR(INDEX(_Helper!$A$2:$A$212,MATCH(26,_Helper!$E$2:$E$212,0)),"") | E32: =IFERROR(INDEX(_Helper!$D$2:$D$212,MATCH(26,_Helper!$E$2:$E$212,0)),"")
A33: =IFERROR(IF(MATCH(27,_Helper!$E$2:$E$212,0)>0,27,""),"") | B33: =IFERROR(INDEX(_Helper!$B$2:$B$212,MATCH(27,_Helper!$E$2:$E$212,0)),"") | C33: =IFERROR(INDEX(_Helper!$C$2:$C$212,MATCH(27,_Helper!$E$2:$E$212,0)),"") | D33: =IFERROR(INDEX(_Helper!$A$2:$A$212,MATCH(27,_Helper!$E$2:$E$212,0)),"") | E33: =IFERROR(INDEX(_Helper!$D$2:$D$212,MATCH(27,_Helper!$E$2:$E$212,0)),"")
A34: =IFERROR(IF(MATCH(28,_Helper!$E$2:$E$212,0)>0,28,""),"") | B34: =IFERROR(INDEX(_Helper!$B$2:$B$212,MATCH(28,_Helper!$E$2:$E$212,0)),"") | C34: =IFERROR(INDEX(_Helper!$C$2:$C$212,MATCH(28,_Helper!$E$2:$E$212,0)),"") | D34: =IFERROR(INDEX(_Helper!$A$2:$A$212,MATCH(28,_Helper!$E$2:$E$212,0)),"") | E34: =IFERROR(INDEX(_Helper!$D$2:$D$212,MATCH(28,_Helper!$E$2:$E$212,0)),"")
A35: =IFERROR(IF(MATCH(29,_Helper!$E$2:$E$212,0)>0,29,""),"") | B35: =IFERROR(INDEX(_Helper!$B$2:$B$212,MATCH(29,_Helper!$E$2:$E$212,0)),"") | C35: =IFERROR(INDEX(_Helper!$C$2:$C$212,MATCH(29,_Helper!$E$2:$E$212,0)),"") | D35: =IFERROR(INDEX(_Helper!$A$2:$A$212,MATCH(29,_Helper!$E$2:$E$212,0)),"") | E35: =IFERROR(INDEX(_Helper!$D$2:$D$212,MATCH(29,_Helper!$E$2:$E$212,0)),"")
A36: =IFERROR(IF(MATCH(30,_Helper!$E$2:$E$212,0)>0,30,""),"") | B36: =IFERROR(INDEX(_Helper!$B$2:$B$212,MATCH(30,_Helper!$E$2:$E$212,0)),"") | C36: =IFERROR(INDEX(_Helper!$C$2:$C$212,MATCH(30,_Helper!$E$2:$E$212,0)),"") | D36: =IFERROR(INDEX(_Helper!$A$2:$A$212,MATCH(30,_Helper!$E$2:$E$212,0)),"") | E36: =IFERROR(INDEX(_Helper!$D$2:$D$212,MATCH(30,_Helper!$E$2:$E$212,0)),"")
A37: =IFERROR(IF(MATCH(31,_Helper!$E$2:$E$212,0)>0,31,""),"") | B37: =IFERROR(INDEX(_Helper!$B$2:$B$212,MATCH(31,_Helper!$E$2:$E$212,0)),"") | C37: =IFERROR(INDEX(_Helper!$C$2:$C$212,MATCH(31,_Helper!$E$2:$E$212,0)),"") | D37: =IFERROR(INDEX(_Helper!$A$2:$A$212,MATCH(31,_Helper!$E$2:$E$212,0)),"") | E37: =IFERROR(INDEX(_Helper!$D$2:$D$212,MATCH(31,_Helper!$E$2:$E$212,0)),"")
A38: =IFERROR(IF(MATCH(32,_Helper!$E$2:$E$212,0)>0,32,""),"") | B38: =IFERROR(INDEX(_Helper!$B$2:$B$212,MATCH(32,_Helper!$E$2:$E$212,0)),"") | C38: =IFERROR(INDEX(_Helper!$C$2:$C$212,MATCH(32,_Helper!$E$2:$E$212,0)),"") | D38: =IFERROR(INDEX(_Helper!$A$2:$A$212,MATCH(32,_Helper!$E$2:$E$212,0)),"") | E38: =IFERROR(INDEX(_Helper!$D$2:$D$212,MATCH(32,_Helper!$E$2:$E$212,0)),"")
A39: =IFERROR(IF(MATCH(33,_Helper!$E$2:$E$212,0)>0,33,""),"") | B39: =IFERROR(INDEX(_Helper!$B$2:$B$212,MATCH(33,_Helper!$E$2:$E$212,0)),"") | C39: =IFERROR(INDEX(_Helper!$C$2:$C$212,MATCH(33,_Helper!$E$2:$E$212,0)),"") | D39: =IFERROR(INDEX(_Helper!$A$2:$A$212,MATCH(33,_Helper!$E$2:$E$212,0)),"") | E39: =IFERROR(INDEX(_Helper!$D$2:$D$212,MATCH(33,_Helper!$E$2:$E$212,0)),"")
A40: =IFERROR(IF(MATCH(34,_Helper!$E$2:$E$212,0)>0,34,""),"") | B40: =IFERROR(INDEX(_Helper!$B$2:$B$212,MATCH(34,_Helper!$E$2:$E$212,0)),"") | C40: =IFERROR(INDEX(_Helper!$C$2:$C$212,MATCH(34,_Helper!$E$2:$E$212,0)),"") | D40: =IFERROR(INDEX(_Helper!$A$2:$A$212,MATCH(34,_Helper!$E$2:$E$212,0)),"") | E40: =IFERROR(INDEX(_Helper!$D$2:$D$212,MATCH(34,_Helper!$E$2:$E$212,0)),"")
A41: =IFERROR(IF(MATCH(35,_Helper!$E$2:$E$212,0)>0,35,""),"") | B41: =IFERROR(INDEX(_Helper!$B$2:$B$212,MATCH(35,_Helper!$E$2:$E$212,0)),"") | C41: =IFERROR(INDEX(_Helper!$C$2:$C$212,MATCH(35,_Helper!$E$2:$E$212,0)),"") | D41: =IFERROR(INDEX(_Helper!$A$2:$A$212,MATCH(35,_Helper!$E$2:$E$212,0)),"") | E41: =IFERROR(INDEX(_Helper!$D$2:$D$212,MATCH(35,_Helper!$E$2:$E$212,0)),"")
A42: =IFERROR(IF(MATCH(36,_Helper!$E$2:$E$212,0)>0,36,""),"") | B42: =IFERROR(INDEX(_Helper!$B$2:$B$212,MATCH(36,_Helper!$E$2:$E$212,0)),"") | C42: =IFERROR(INDEX(_Helper!$C$2:$C$212,MATCH(36,_Helper!$E$2:$E$212,0)),"") | D42: =IFERROR(INDEX(_Helper!$A$2:$A$212,MATCH(36,_Helper!$E$2:$E$212,0)),"") | E42: =IFERROR(INDEX(_Helper!$D$2:$D$212,MATCH(36,_Helper!$E$2:$E$212,0)),"")
A43: =IFERROR(IF(MATCH(37,_Helper!$E$2:$E$212,0)>0,37,""),"") | B43: =IFERROR(INDEX(_Helper!$B$2:$B$212,MATCH(37,_Helper!$E$2:$E$212,0)),"") | C43: =IFERROR(INDEX(_Helper!$C$2:$C$212,MATCH(37,_Helper!$E$2:$E$212,0)),"") | D43: =IFERROR(INDEX(_Helper!$A$2:$A$212,MATCH(37,_Helper!$E$2:$E$212,0)),"") | E43: =IFERROR(INDEX(_Helper!$D$2:$D$212,MATCH(37,_Helper!$E$2:$E$212,0)),"")
...
